Workbook

Sheet OCT
A1: Tipo de documento | B1: CUFE/CUDE | C1: Folio | D1: Prefijo | E1: Fecha Emisión | F1: Fecha Recepción | G1: NIT Emisor | H1: Nombre Emisor | I1: Subtotal | J1: IVA | K1: Total | L1: Responsable | M1: FECHA DE ENTREGA | N1: RANGO DE ENTREGA DIAS | O1: QUIEN ENTREGA | P1: NOMBRE A QUIEN SE DEVUELVE | Q1: FECHA DEVOLUCION | R1: REINTEGRO | S1: FECHA ENTREGA TESORERIA
N3: =IF(-_xlfn.DAYS(E3,M3)<0,0,-_xlfn.DAYS(E3,M3)) -> 0

Sheet NOV
A1: Tipo de documento | B1: CUFE/CUDE | C1: Folio | D1: Prefijo | E1: Fecha Emisión | F1: Fecha Recepción | G1: NIT Emisor | H1: Nombre Emisor | I1: Subtotal | J1: IVA | K1: Total | L1: Responsable | M1: FECHA DE ENTREGA | N1: RANGO DE ENTREGA DIAS | O1: QUIEN ENTREGA | P1: NOMBRE A QUIEN SE DEVUELVE | Q1: FECHA DEVOLUCION | R1: REINTEGRO | S1: FECHA ENTREGA TESORERIA
N3: =IF(-_xlfn.DAYS(E3,M3)<0,0,-_xlfn.DAYS(E3,M3)) -> 0

Sheet DIC
A1: Tipo de documento | B1: CUFE/CUDE | C1: Folio | D1: Prefijo | E1: Fecha Emisión | F1: Fecha Recepción | G1: NIT Emisor | H1: Nombre Emisor | I1: Subtotal | J1: IVA | K1: Total | L1: Responsable | M1: FECHA DE ENTREGA | N1: RANGO DE ENTREGA DIAS | O1: QUIEN ENTREGA | P1: NOMBRE A QUIEN SE DEVUELVE | Q1: FECHA DEVOLUCION | R1: REINTEGRO | S1: FECHA ENTREGA TESORERIA
N3: =IF(-_xlfn.DAYS(E3,M3)<0,0,-_xlfn.DAYS(E3,M3)) -> 0

Sheet ENERO
A1: Tipo documento | B1: CUFE/CUDE | C1: Folio | D1: Prefijo | E1: Fecha Emisión | F1: Fecha Recepción | G1: NIT | H1: Nombre Emisor | I1: Subtotal | J1: IVA | K1: Total | L1: Responsable | M1: FECHA DE ENTREGA | N1: DÍAS DE ENTREGA A CONTABILIDAD | O1: QUIEN ENTREGA | P1: NOMBRE A QUIEN SE DEVUELVE | Q1: FECHA DEVOLUCION | R1: REINTEGRO | S1: RANGO DE ENTREGA A TESORERIA DIAS | T1: FECHA ENTREGA TESORERIA | U1: REQUIERE FIRMA DE GERENCIA | V1: FIRMADAS | W1: RANGO DÍAS DE ENTREGA
A2: Factura electrónica | B2: 87ddcf5ecab4c8d8a9db5393ab38442822d2b08ab664baac6a2caf9e6a22d5de7dcc5dfc73bc6b5517f0b8683f56c939 | C2: 3512 | D2: FE | E2: 46044 | F2: 46044.457 | G2: 811027589 | H2: Zonalogística S.A.S ZLG | I2: =K2-J2 -> 12048400 | J2: 2289196 | K2: 14337596 | L2: GERENCIA | M2: 46051 | N2: =IFERROR(IF(-_xlfn.DAYS(E2,M2)<0,0,-_xlfn.DAYS(E2,M2)), " - ") -> 7 | O2: ANGELA SEPULVEDA | T2: 46057 | U2: SI | W2: 6 a 10
A3: Factura electrónica | B3: e19a155a90b793b91be3542d9a010f3420db282ee75f7584134eb96bd29690d21824eb3cc144c81bb0a1a913216ddf7f | C3: 485 | D3: WC | E3: 46028 | F3: 46028.845 | G3: 901741749 | H3: WORLD CRANES SAS | I3: =K3-J3 -> 8450000 | J3: 1605500 | K3: 10055500 | L3: MANTENIMIENTO | M3: 46030 | N3: =IFERROR(IF(-_xlfn.DAYS(E3,M3)<0,0,-_xlfn.DAYS(E3,M3)), " - ") -> 2 | O3: YENIFER PARRA | T3: 46044 | U3: NO | W3: 0 a 5
A4: Factura electrónica | B4: 04a2398fe369568a1352ac79a927d7de329dc854fa6f340ed9a6c5fd12ef5cd56708eb4eef5e87218816d347f2f74369 | C4: 488 | D4: WC | E4: 46030 | F4: 46030.491 | G4: 901741749 | H4: WORLD CRANES SAS | I4: =K4-J4 -> 800000 | J4: 152000 | K4: 952000 | L4: MANTENIMIENTO | M4: 46030 | N4: =IFERROR(IF(-_xlfn.DAYS(E4,M4)<0,0,-_xlfn.DAYS(E4,M4)), " - ") -> 0 | O4: YENIFER PARRA | T4: 46044 | U4: NO | W4: 0 a 5
A5: Factura electrónica | B5: 045077b960eea26c79b2996fce29de61548aab3f3700f5c7abaf377db39c7fd37152003449b458bf8145845a785adb41 | C5: 498 | D5: WC | E5: 46037 | F5: 46037.79 | G5: 901741749 | H5: WORLD CRANES SAS | I5: =K5-J5 -> 150000 | J5: 28500 | K5: 178500 | L5: MANTENIMIENTO | M5: 46042 | N5: =IFERROR(IF(-_xlfn.DAYS(E5,M5)<0,0,-_xlfn.DAYS(E5,M5)), " - ") -> 5 | O5: YENIFER PARRA | T5: 46044 | U5: no | W5: 0 a 5
A6: Factura electrónica | B6: f99e39cec77c247d93fc9f99a2db9cb09dcfc6f4e64288e59d2351554d874f43dbfe406ea41d4d372d48f0241328cac8 | C6: 497 | D6: WC | E6: 46037 | F6: 46037.779 | G6: 901741749 | H6: WORLD CRANES SAS | I6: =K6-J6 -> 3600000 | J6: 684000 | K6: 4284000 | L6: MANTENIMIENTO | M6: 46042 | N6: =IFERROR(IF(-_xlfn.DAYS(E6,M6)<0,0,-_xlfn.DAYS(E6,M6)), " - ") -> 5 | O6: YENIFER PARRA | T6: 46065 | U6: NO | W6: 0 a 5
A7: Factura electrónica | B7: 71e2920798ae794d2e481dc362b006e33bfd7ae63b22bf9851998071c2897e9a421de1b63e29fd3f2a495f16b94d8760 | C7: 503 | D7: WC | E7: 46044 | F7: 46044.817 | G7: 901741749 | H7: WORLD CRANES SAS | I7: =K7-J7 -> 1600000 | J7: 304000 | K7: 1904000 | L7: MANTENIMIENTO | M7: 46048 | N7: =IFERROR(IF(-_xlfn.DAYS(E7,M7)<0,0,-_xlfn.DAYS(E7,M7)), " - ") -> 4 | O7: YENIFER PARRA | T7: 46063 | U7: NO | W7: 0 a 5
A8: Factura electrónica | B8: 0ea2237f5d6eb476d3ca358aa03319e9c1ed16a7e760cb1da1e9c5ca5da8ec5b1ef537947a3be90402f18903ec5776e6 | C8: 507 | D8: WC | E8: 46046 | F8: 46046.465 | G8: 901741749 | H8: WORLD CRANES SAS | I8: =K8-J8 -> 4600000 | J8: 874000 | K8: 5474000 | L8: MANTENIMIENTO | M8: 46049 | N8: =IFERROR(IF(-_xlfn.DAYS(E8,M8)<0,0,-_xlfn.DAYS(E8,M8)), " - ") -> 3 | O8: YENIFER PARRA | T8: 46065 | U8: NO | W8: 0 a 5
A9: Factura electrónica | B9: eed87bf76288b3850294da00aaa166da031877072c21d09e2ed8b6bb87e47c88cdc92e58abf3ab1994972a063116e61e | C9: 637 | D9: WME | E9: 46038 | F9: 46038.602 | G9: 900618518 | H9: WIRE MACHINE S A S | I9: =K9-J9 -> 54881267 | J9: 10427441 | K9: 65308708 | L9: MANTENIMIENTO | M9: 46059 | N9: =IFERROR(IF(-_xlfn.DAYS(E9,M9)<0,0,-_xlfn.DAYS(E9,M9)), " - ") -> 21 | O9: YENIFER PARRA | T9: 46065 | U9: NO | W9: Más de 10
A10: Factura electrónica | B10: 177166b32fe40e7929fac9f1ef4632be7101b736c8e11d4c6dcc007a93238101d0b7431152a355b5469a056df985d150 | C10: 3397 | D10: FDR | E10: 46028 | F10: 46028.697 | G10: 70907060 | H10: WILINTON DUQUE GONZALEZ | I10: =K10-J10 -> 123100 | J10: 0 | K10: 123100 | L10: CAJA MENOR | N10: =IFERROR(IF(-_xlfn.DAYS(E10,M10)<0,0,-_xlfn.DAYS(E10,M10)), " - ") -> 0
A11: Factura electrónica | B11: 5dd4b0f8183b2ed9b34e3d80ca18f0fb5eb6cd855505e6c6af3b50650a842cc10dc90216225f828795d4f40ef0959040 | C11: 8985 | D11: FEVV | E11: 46050 | F11: 46050.688 | G11: 901242715 | H11: VIANCO TE TRANSPORTA SAS | I11: =K11-J11 -> 1470000 | J11: 0 | K11: 1470000 | L11: OPERACIONES | M11: 46056 | N11: =IFERROR(IF(-_xlfn.DAYS(E11,M11)<0,0,-_xlfn.DAYS(E11,M11)), " - ") -> 6 | O11: YENIFER PARRA | T11: 46058 | U11: NO | W11: 6 a 10
A12: Factura electrónica | B12: 7e447ce310a7a5a2fcde31c65f23fb50b1cecce2daa2e37ab0528a40460c28ecead8bcc544f5dfc89101ffdf7bd0af7a | C12: 18449 | D12: 033 | E12: 46035 | F12: 46035.377 | G12: 890901389 | H12: UNIVERSIDAD EAFIT | I12: =K12-J12 -> 3014783 | J12: 0 | K12: 3014783 | L12: BIENESTAR | M12: 46035 | N12: =IFERROR(IF(-_xlfn.DAYS(E12,M12)<0,0,-_xlfn.DAYS(E12,M12)), " - ") -> 0 | O12: ANGELA SEPULVEDA | T12: 46037 | U12: NO | W12: 0 a 5
A13: Factura electrónica | B13: 0e7931ad3560f20bd514088cc1cbb780bdc318b13d20ceb4a98e65c8946fe62553688cc5011d8b5c28facfcc5036e94e | C13: 296930 | D13: FE | E13: 46030 | F13: 46030.587 | G13: 811021363 | H13: UNIPLES S.A.S. | I13: =K13-J13 -> 371184 | J13: 70524.96 | K13: 441708.96 | L13: TI | M13: 46035 | N13: =IFERROR(IF(-_xlfn.DAYS(E13,M13)<0,0,-_xlfn.DAYS(E13,M13)), " - ") -> 5 | O13: FRANCY SALAS | T13: 46036 | U13: NO | W13: 0 a 5
A14: Factura electrónica | B14: bd1c26409c6a8e4dd3711fd6bf85e51a60c6ed98522afc01ad2a478007302589c57094c825acfeaf297023a6675efe32 | C14: 7265 | D14: U | E14: 46037 | F14: 46037.635 | G14: 901233261 | H14: UNIFORMAR ORIENTE S.A.S | I14: =K14-J14 -> 25212 | J14: 4790.28 | K14: 30002.28 | L14: COMPRAS | M14: 46052 | N14: =IFERROR(IF(-_xlfn.DAYS(E14,M14)<0,0,-_xlfn.DAYS(E14,M14)), " - ") -> 15 | O14: YENIFER PARRA | T14: 46062 | W14: Más de 10
A15: Factura electrónica | B15: da433de26906494786888503b13cba4d9a41975983cc338308956235f3f08f2029503a97837726d0bb1d57b71d5c1f60 | C15: 2874 | D15: FE | E15: 46030 | F15: 46030.463 | G15: 900144364 | H15: UNIDOTAMOS SAS | I15: =K15-J15 -> 14101800 | J15: 2679342 | K15: 16781142 | L15: COMPRAS | M15: 46042 | N15: =IFERROR(IF(-_xlfn.DAYS(E15,M15)<0,0,-_xlfn.DAYS(E15,M15)), " - ") -> 12 | O15: YENIFER PARRA | T15: 46045 | U15: SI | W15: Más de 10
A16: Factura electrónica | B16: 6dfa51d5ca1b744c065b3b3d64994e5c3d0be325e6567257754be51e152df24b0fd77138505475aa6ff20c48fbea2f75 | C16: 2880 | D16: FE | E16: 46038 | F16: 46038.617 | G16: 900144364 | H16: UNIDOTAMOS SAS | I16: =K16-J16 -> 30000 | J16: 5700 | K16: 35700 | L16: COMPRAS | M16: 46041 | N16: =IFERROR(IF(-_xlfn.DAYS(E16,M16)<0,0,-_xlfn.DAYS(E16,M16)), " - ") -> 3 | O16: YENIFER PARRA | T16: 46042 | U16: NO | W16: 0 a 5
A17: Factura electrónica | B17: 45101e4f8639c51804e55b58cabc89ce3c957410b848643232bd2a0a3e481fbb9a8b1fe4c709951b4d31f260e9d7656a | C17: 2879 | D17: FE | E17: 46038 | F17: 46038.376 | G17: 900144364 | H17: UNIDOTAMOS SAS | I17: =K17-J17 -> 1794500 | J17: 340955 | K17: 2135455 | L17: COMPRAS | M17: 46041 | N17: =IFERROR(IF(-_xlfn.DAYS(E17,M17)<0,0,-_xlfn.DAYS(E17,M17)), " - ") -> 3 | O17: YENIFER PARRA | T17: 46042 | U17: NO | W17: 0 a 5
A18: Factura electrónica | B18: f70dfc90f596f0ab14b6aa306dd0ce0d120f69b31f7340622efb0b684398b49eb75833422879104ffc0888f758d2335d | C18: 2878 | D18: FE | E18: 46038 | F18: 46038.366 | G18: 900144364 | H18: UNIDOTAMOS SAS | I18: =K18-J18 -> 8747800 | J18: 1662082 | K18: 10409882 | L18: COMPRAS | M18: 46042 | N18: =IFERROR(IF(-_xlfn.DAYS(E18,M18)<0,0,-_xlfn.DAYS(E18,M18)), " - ") -> 4 | O18: YENIFER PARRA | T18: 46045 | U18: SI | W18: 0 a 5
A19: Factura electrónica | B19: 111840da2e41132c62bf77bb9fec297ed9926273075d6f7530f41ef480101143d5cc71afc01be097d6246bf703da6532 | C19: 2891 | D19: FE | E19: 46043 | F19: 46043.589 | G19: 900144364 | H19: UNIDOTAMOS SAS | I19: =K19-J19 -> 1089000 | J19: 206910 | K19: 1295910 | L19: COMPRAS | M19: 46045 | N19: =IFERROR(IF(-_xlfn.DAYS(E19,M19)<0,0,-_xlfn.DAYS(E19,M19)), " - ") -> 2 | O19: FRANCY SALAS | T19: 46048 | U19: NO | W19: 0 a 5
A20: Factura electrónica | B20: c2f630fc67f892b5818009c3cc6acab892eb98ae81845235fba3375c64e4cec5e6d3bd581c8ea69178ca7fe462770c50 | C20: 2890 | D20: FE | E20: 46043 | F20: 46043.539 | G20: 900144364 | H20: UNIDOTAMOS SAS | I20: =K20-J20 -> 332950 | J20: 63260.5 | K20: 396210.5 | L20: COMPRAS | M20: 46045 | N20: =IFERROR(IF(-_xlfn.DAYS(E20,M20)<0,0,-_xlfn.DAYS(E20,M20)), " - ") -> 2 | O20: FRANCY SALAS | T20: 46048 | U20: NO | W20: 0 a 5
A21: Factura electrónica | B21: 3b5623790c7d54546ba985f5ea24dda565744a3a8dda580b3ed671a46eb2d37d73c3bbabb89e9fd5c7698dcb18de45ec | C21: 2889 | D21: FE | E21: 46043 | F21: 46043.532 | G21: 900144364 | H21: UNIDOTAMOS SAS | I21: =K21-J21 -> 1478700 | J21: 280953 | K21: 1759653 | L21: COMPRAS | M21: 46045 | N21: =IFERROR(IF(-_xlfn.DAYS(E21,M21)<0,0,-_xlfn.DAYS(E21,M21)), " - ") -> 2 | O21: FRANCY SALAS | T21: 46048 | U21: NO | W21: 0 a 5
A22: Factura electrónica | B22: bf2b2e78d923fe2b54c7cf6316edfd75442216a5bba7de33a38cdeebcd6811477c4258105b18b958475986062dacb53b | C22: 2888 | D22: FE | E22: 46043 | F22: 46043.525 | G22: 900144364 | H22: UNIDOTAMOS SAS | I22: =K22-J22 -> 1224300 | J22: 232617 | K22: 1456917 | L22: CRUZA | M22: N/A | N22: =IFERROR(IF(-_xlfn.DAYS(E22,M22)<0,0,-_xlfn.DAYS(E22,M22)), " - ") -> -
A23: Nota de crédito electrónica | B23: afb8ced3d655ed16dc3912c045dbdfc9bafa49b4feec01121f1a76f4a4be430c83f0d9751ce8514298351a12a4590bff | C23: 222 | D23: DV | E23: 46043 | F23: 46043.528 | G23: 900144364 | H23: UNIDOTAMOS SAS | I23: =K23-J23 -> 1224300 | J23: 232617 | K23: 1456917 | L23: CRUZA | M23: N/A | N23: =IFERROR(IF(-_xlfn.DAYS(E23,M23)<0,0,-_xlfn.DAYS(E23,M23)), " - ") -> -
A24: Factura electrónica | B24: 0ae6caba569fd68845dc2b8ddffaf4cf3d9fa3d676261dd260326f2900e31a3f8dece8454a01aaa4453747e763c6677e | C24: 2894 | D24: FE | E24: 46044 | F24: 46044.473 | G24: 900144364 | H24: UNIDOTAMOS SAS | I24: =K24-J24 -> 426600 | J24: 81054 | K24: 507654 | L24: COMPRAS | M24: 46045 | N24: =IFERROR(IF(-_xlfn.DAYS(E24,M24)<0,0,-_xlfn.DAYS(E24,M24)), " - ") -> 1 | O24: FRANCY SALAS | T24: 46048 | U24: NO | W24: 0 a 5
A25: Factura electrónica | B25: a87be2aff47fa9b5810238973bd14b12eea6a93df0ede9f2f321b1283dbf3eff2db88448ed9751e77ed11f6616d2feab | C25: 2893 | D25: FE | E25: 46044 | F25: 46044.472 | G25: 900144364 | H25: UNIDOTAMOS SAS | I25: =K25-J25 -> 2001500 | J25: 380285 | K25: 2381785 | L25: COMPRAS | M25: 46045 | N25: =IFERROR(IF(-_xlfn.DAYS(E25,M25)<0,0,-_xlfn.DAYS(E25,M25)), " - ") -> 1 | O25: FRANCY SALAS | T25: 46048 | U25: NO | W25: 0 a 5
A26: Factura electrónica | B26: c91eb22e20820d032dace3e2dbf0b3a272ad893774ede531d4a82b8790d351d47de09416e111c21a8a36f6981ea8234e | C26: 130189358 | D26: BOPU | E26: 46040 | F26: 46040.63 | G26: 900092385 | H26: UNE EPM TELECOMUNICACIONES S.A | I26: =K26-J26 -> 537968.89 | J26: 102214.11 | K26: 640183 | L26: TI | M26: 46044 | N26: =IFERROR(IF(-_xlfn.DAYS(E26,M26)<0,0,-_xlfn.DAYS(E26,M26)), " - ") -> 4 | O26: JAIME GARCIA | T26: 46045 | U26: NO | W26: 0 a 5
A27: Factura electrónica | B27: 258a8c4351a08e73264804adf1c180639711b03a82c708b91da6a590ccd199c95b89118737b28fe46fdf1ce648470364 | C27: 130131606 | D27: BOPU | E27: 46040 | F27: 46040.554 | G27: 900092385 | H27: UNE EPM TELECOMUNICACIONES S.A | I27: =K27-J27 -> 277962.4 | J27: 49206.6 | K27: 327169 | L27: TI | M27: 46044 | N27: =IFERROR(IF(-_xlfn.DAYS(E27,M27)<0,0,-_xlfn.DAYS(E27,M27)), " - ") -> 4 | O27: JAIME GARCIA | T27: 46045 | U27: NO | W27: 0 a 5
A28: Factura electrónica | B28: e57ba40dfe11031a4408406ef0a534f623e6b187e457033d3503889de1a0cad413c04da18b5d45f9f25201555bd690ff | C28: 130189824 | D28: BOPU | E28: 46040 | F28: 46040.446 | G28: 900092385 | H28: UNE EPM TELECOMUNICACIONES S.A | I28: =K28-J28 -> 537968.89 | J28: 102214.11 | K28: 640183 | L28: TI | M28: 46044 | N28: =IFERROR(IF(-_xlfn.DAYS(E28,M28)<0,0,-_xlfn.DAYS(E28,M28)), " - ") -> 4 | O28: JAIME GARCIA | T28: 46045 | U28: NO | W28: 0 a 5
A29: Factura electrónica | B29: 44c33ba0bd64e4f978603945a6ad98c9620a6c7d712ba0c13f6c4b7a55d44eb811d12fb542b193fd6aac4a91ea32a8eb | C29: 130238404 | D29: BOPU | E29: 46044 | F29: 46044.627 | G29: 900092385 | H29: UNE EPM TELECOMUNICACIONES S.A | I29: =K29-J29 -> 22984.04 | J29: 4366.96 | K29: 27351 | L29: TI | M29: 46048 | N29: =IFERROR(IF(-_xlfn.DAYS(E29,M29)<0,0,-_xlfn.DAYS(E29,M29)), " - ") -> 4 | O29: JAIME GARCIA | T29: 46049 | U29: NO | W29: 0 a 5
A30: Factura electrónica | B30: 363c2a4575972f7aef623b0ac082a60a9b806f65fb5fde195212192dc233baf0c3d1303be6671326fd6121a6385b007a | C30: 6856 | D30: RGRO | E30: 46037 | F30: 46037.601 | G30: 811006418 | H30: TRULY NOLEN SOLUCIONES S.A.S | I30: =K30-J30 -> 295766 | J30: 56195.54 | K30: 351961.54 | L30: CALIDAD | M30: 46042 | N30: =IFERROR(IF(-_xlfn.DAYS(E30,M30)<0,0,-_xlfn.DAYS(E30,M30)), " - ") -> 5 | O30: YENIFER PARRA | T30: 46042 | U30: NO | W30: 0 a 5
A31: Factura electrónica | B31: 945895c2157bbc6c9c043b127ea7dad32d7ecc589cdce9bfb55c1ea8b19616f3307791c3ca70ef47c045bdb7d1b61720 | C31: 6855 | D31: RGRO | E31: 46037 | F31: 46037.596 | G31: 811006418 | H31: TRULY NOLEN SOLUCIONES S.A.S | I31: =K31-J31 -> 517045 | J31: 98238.55 | K31: 615283.55 | L31: CALIDAD | M31: 46042 | N31: =IFERROR(IF(-_xlfn.DAYS(E31,M31)<0,0,-_xlfn.DAYS(E31,M31)), " - ") -> 5 | O31: YENIFER PARRA | T31: 46042 | U31: NO | W31: 0 a 5
A32: Factura electrónica | B32: 6bcee3a69612e911bfe5cbaf9280712d902d8d10b25936c2b34afb7a62df1c4ade537ad1c7e0428c02eb176ce1b1b615 | C32: 6854 | D32: RGRO | E32: 46037 | F32: 46037.594 | G32: 811006418 | H32: TRULY NOLEN SOLUCIONES S.A.S | I32: =K32-J32 -> 130000 | J32: 24700 | K32: 154700 | L32: CALIDAD | M32: 46042 | N32: =IFERROR(IF(-_xlfn.DAYS(E32,M32)<0,0,-_xlfn.DAYS(E32,M32)), " - ") -> 5 | O32: YENIFER PARRA | T32: 46044 | U32: NO | W32: 0 a 5
A33: Factura electrónica | B33: 836d97511a2f671fcad83dc427dcc60de97ba31f1845a4eddd1023e255780c75cf78945853949eaeb5edb32065f1f872 | C33: 30884 | D33: MEDN | E33: 46042 | F33: 46042.683 | G33: 811006418 | H33: TRULY NOLEN SOLUCIONES S.A.S | I33: =K33-J33 -> 290500 | J33: 55195 | K33: 345695 | L33: CALIDAD | M33: 46045 | N33: =IFERROR(IF(-_xlfn.DAYS(E33,M33)<0,0,-_xlfn.DAYS(E33,M33)), " - ") -> 3 | O33: FRANCY SALAS | T33: 46065 | U33: NO | W33: 0 a 5
A34: Factura electrónica | B34: cc1f16ca45b90325b0de78b9cdca079cb0e9bf32dfec7e5c12e6f10ed867ede5925d2a79fe45fc6d36b19627702c03ae | C34: 7788 | D34: PERE | E34: 46042 | F34: 46042.61 | G34: 811006418 | H34: TRULY NOLEN SOLUCIONES S.A.S | I34: =K34-J34 -> 320787 | J34: 60949.53 | K34: 381736.53 | L34: CALIDAD | M34: 46045 | N34: =IFERROR(IF(-_xlfn.DAYS(E34,M34)<0,0,-_xlfn.DAYS(E34,M34)), " - ") -> 3 | O34: FRANCY SALAS | T34: 46063 | U34: NO | W34: 0 a 5
A35: Factura electrónica | B35: 295411022c206b07c5f77cf5ef8dd8304c879dfd96fa48a0436908c451dae00a96e28977079e033f4807953c972a7771 | C35: 587 | D35: TEC | E35: 46048 | F35: 46048.938 | G35: 901161036 | H35: TRANSPORTES ESPECIALES DEL CAUCA S.A.S. | I35: =K35-J35 -> 13216000 | J35: 2511040 | K35: 15727040 | L35: OPERACIONES | M35: 46057 | N35: =IFERROR(IF(-_xlfn.DAYS(E35,M35)<0,0,-_xlfn.DAYS(E35,M35)), " - ") -> 9 | O35: YENIFER PARRA | T35: 46065 | U35: SI | W35: 6 a 10
A36: Factura electrónica | B36: 636076945bf077ee9c21f01ebd30eaa98781d759d0692d1f87f5a81817855d4163a0ca34cd37c77d9229a58e9be78e30 | C36: 586 | D36: TEC | E36: 46048 | F36: 46048.929 | G36: 901161036 | H36: TRANSPORTES ESPECIALES DEL CAUCA S.A.S. | I36: =K36-J36 -> 44030000 | J36: 8365700 | K36: 52395700 | L36: OPERACIONES | M36: 46057 | N36: =IFERROR(IF(-_xlfn.DAYS(E36,M36)<0,0,-_xlfn.DAYS(E36,M36)), " - ") -> 9 | O36: YENIFER PARRA | T36: 46065 | U36: SI | W36: 6 a 10
A37: Factura electrónica | B37: 2d2325d218c892809b2bd01632a36d5870de81323f40dce15a04bdc1c1a2486246ca2366e67e648afffdc038e02d98ae | C37: 585 | D37: TEC | E37: 46048 | F37: 46048.922 | G37: 901161036 | H37: TRANSPORTES ESPECIALES DEL CAUCA S.A.S. | I37: =K37-J37 -> 905000 | J37: 171950 | K37: 1076950 | L37: CRUZA | M37: N/A | N37: =IFERROR(IF(-_xlfn.DAYS(E37,M37)<0,0,-_xlfn.DAYS(E37,M37)), " - ") -> - | O37: YENIFER PARRA
A38: Factura electrónica | B38: 855e30eb0d277a2c88f7798681807f82369b822c5e62971604179852975acb16bfd80fb71a4c8a9a54bed4b72c6e0659 | C38: 194973 | D38: FETN | E38: 46027 | F38: 46027.323 | G38: 890903229 | H38: TRANSPORTES CHACHAFRUTO S.A. | I38: =K38-J38 -> 23000 | J38: 0 | K38: 23000 | L38: CAJA MENOR | N38: =IFERROR(IF(-_xlfn.DAYS(E38,M38)<0,0,-_xlfn.DAYS(E38,M38)), " - ") -> 0
A39: Factura electrónica | B39: 6f76d7286ffecbb8c4801bdb5beb26f287fe4c9b86b4148a0ac9595d2aa3f321de2275e2ad31397334c9928eb2cfc94a | C39: 6199 | D39: TL | E39: 46029 | F39: 46029.581 | G39: 900036588 | H39: TRAMAS LITOGRAFIA SAS | I39: =K39-J39 -> 584550 | J39: 111064.5 | K39: 695614.5 | L39: COMPRAS | M39: 46030 | N39: =IFERROR(IF(-_xlfn.DAYS(E39,M39)<0,0,-_xlfn.DAYS(E39,M39)), " - ") -> 1 | O39: YENIFER PARRA | T39: 46044 | U39: NO | W39: 0 a 5
A40: Factura electrónica | B40: bcfdb983d2d4bd24acdf0484ba70176cf169980ced16224958736781b921853d9cf3ccb43b70303cc3790f933ee420d4 | C40: 6198 | D40: TL | E40: 46029 | F40: 46029.58 | G40: 900036588 | H40: TRAMAS LITOGRAFIA SAS | I40: =K40-J40 -> 33183 | J40: 6304.77 | K40: 39487.77 | L40: COMPRAS | M40: 46030 | N40: =IFERROR(IF(-_xlfn.DAYS(E40,M40)<0,0,-_xlfn.DAYS(E40,M40)), " - ") -> 1 | O40: YENIFER PARRA | T40: 46044 | U40: NO | W40: 0 a 5
...

Sheet FEBRERO
B1: CUFE/CUDE | C1: Folio | D1: Prefijo | E1: Fecha Emisión | F1: Fecha Recepción | G1: NIT | H1: Nombre Emisor | I1: Subtotal | J1: IVA | K1: Total | L1: Responsable | M1: FECHA DE ENTREGA | N1: DÍAS DE ENTREGA A CONTABILIDAD | O1: QUIEN ENTREGA | P1: NOMBRE A QUIEN SE DEVUELVE | Q1: FECHA DEVOLUCION | R1: REINTEGRO | S1: RANGO DE ENTREGA A TESORERIA DIAS | T1: FECHA ENTREGA TESORERIA | U1: REQUIERE FIRMA DE GERENCIA | V1: FIRMADAS | W1: RANGO DÍAS DE ENTREGA | X1: MES DEL SERVICIO
A2: Factura electrónica | B2: 4de1d08c12bff4f13d87fc5f171cf87347f63e11472aba726cde2d27513f26ea8d4e1d06fc7447e8e6ef3af720112231 | C2: 452889 | D2: IFXC | E2: 46054 | F2: 46054.758 | G2: 830058677 | H2: IFX NETWORKS COLOMBIA S.A.S. | I2: =K2-J2 -> 13180561 | J2: 2504306.6 | K2: 15684868 | L2: =VLOOKUP(G2,ENERO!G2:L631,6,0) -> TI | M2: 46056 | N2: =IFERROR(IF(-_xlfn.DAYS(E2,M2)<0,0,-_xlfn.DAYS(E2,M2)), " - ") -> 2 | O2: ALEXANDER TABORDA | T2: 46058 | U2: NO | W2: 0 A 5
A3: Factura electrónica | B3: 022ce6b7e6e5d89fa427fd96d78e2a96471a07717f72ca4e53cfd826dbe1277624885ca8266df6cf34e683591c908e30 | C3: 4920 | D3: FEIT | E3: 46054 | F3: 46054.92 | G3: 901042685 | H3: ITTERACTIVO S.A.S. | I3: =K3-J3 -> 1990452 | J3: 0 | K3: 1990452 | L3: =VLOOKUP(G3,ENERO!G3:L632,6,0) -> TI | M3: 46055 | N3: =IFERROR(IF(-_xlfn.DAYS(E3,M3)<0,0,-_xlfn.DAYS(E3,M3)), " - ") -> 1 | O3: ALEXANDER TABORDA | T3: 46058 | U3: NO | W3: 0 A 5
A4: Factura electrónica | B4: 251d206c3b842cde617bdb08ee00c5c31bb13b2db16fd1196196b0037dd40078b1d75797b4cd5cbbd666e1b3749246eb | C4: 36026 | D4: AEZY | E4: 46054 | F4: 46054.186 | G4: 900610585 | H4: Easytaxi Colombia SAS | I4: =K4-J4 -> 3927701 | J4: 102933 | K4: 4030634 | L4: =VLOOKUP(G4,ENERO!G4:L633,6,0) -> COMPRAS | M4: 46056 | N4: =IFERROR(IF(-_xlfn.DAYS(E4,M4)<0,0,-_xlfn.DAYS(E4,M4)), " - ") -> 2 | O4: YENIFER PARRA | T4: 46063 | U4: NO | W4: 0 A 5
A5: Factura electrónica | B5: 9c115d0562effa71779e797d1e2e8efca2f66d7e0e3a9b8b8385cec8a8dff4c790c1c6012c3df3ae2de8b8868b3dd5c9 | C5: 634908 | D5: ECCO | E5: 46054 | F5: 46054.41 | G5: 811009788 | H5: DISTRACOM S.A. | I5: =K5-J5 -> 85030 | J5: 0 | K5: 85030 | L5: =VLOOKUP(G5,ENERO!G5:L634,6,0) -> COMPRAS | M5: 46056 | N5: =IFERROR(IF(-_xlfn.DAYS(E5,M5)<0,0,-_xlfn.DAYS(E5,M5)), " - ") -> 2 | O5: YENIFER PARRA | T5: 46062 | U5: NO | W5: 0 A 5
A6: Factura electrónica | B6: b1cdb399e51e6df685d41c2317d9ab32f3c0c96e367a1f1b9abc1d0f8683e5a5f8e99b533170477464b9468b4beea4cf | C6: 37677 | D6: VFGA | E6: 46054 | F6: 46054.803 | G6: 1088263697 | H6: VALENTINA FERNANDEZ VALENCIA | I6: =K6-J6 -> 31700 | J6: 0 | K6: 31700 | L6: CAJA MENOR | N6: =IFERROR(IF(-_xlfn.DAYS(E6,M6)<0,0,-_xlfn.DAYS(E6,M6)), " - ") -> 0
A7: Factura electrónica | B7: 552243f34aca81451f8cad9f632aeef4650ea2e952b6c9f3a95c78428390b21e629d0da9ce7c4618bddc70470f20c416 | C7: 4892 | D7: FEIT | E7: 46054 | F7: 46054.709 | G7: 901042685 | H7: ITTERACTIVO S.A.S. | I7: =K7-J7 -> 8849107 | J7: 0 | K7: 8849107 | L7: =VLOOKUP(G7,ENERO!G7:L636,6,0) -> TI | M7: 46076 | N7: =IFERROR(IF(-_xlfn.DAYS(E7,M7)<0,0,-_xlfn.DAYS(E7,M7)), " - ") -> 22 | O7: JAIME GARCIA | T7: 46069 | U7: NO | W7: MAS 10
A8: Factura electrónica | B8: feeee341d506c4b0f1d50df0f5979ca4db497e2a7ff214c457614357ae6c32818e7051c7de64bc5c516318b20de00dbb | C8: 19088 | D8: FET | E8: 46054 | F8: 46054.63 | G8: 71656465 | H8: JUAN DAVID FERRER BERNAL | I8: =K8-J8 -> 141100 | J8: 0 | K8: 141100 | L8: CAJA MENOR | N8: =IFERROR(IF(-_xlfn.DAYS(E8,M8)<0,0,-_xlfn.DAYS(E8,M8)), " - ") -> 0
A9: Factura electrónica | B9: f1c518e75af10e54eee6c56f8713f0b205866afbbf1e25ab4671a250bced4e0ee286dcd37a6bd412b5c9ece7da54919d | C9: 292509059 | D9: 3 | E9: 46054 | F9: 46058.724 | G9: 800153993 | H9: COMUNICACION CELULAR S A COMCEL S A | I9: =K9-J9 -> 1967321 | J9: 44197.99 | K9: 2011519 | L9: TI | M9: 46076 | N9: =IFERROR(IF(-_xlfn.DAYS(E9,M9)<0,0,-_xlfn.DAYS(E9,M9)), " - ") -> 22 | O9: JAIME GARCIA | T9: 46071 | U9: NO | W9: MAS 10
A10: Factura electrónica | B10: 2d56d828236951a3feb7ef771598af592cd6048ab817e93780bc1787020f56d8b2a96abb68007484220061a939c7b646 | C10: 1724 | D10: FE | E10: 46055 | F10: 46055.358 | G10: 900609164 | H10: VIREL SAS | I10: =K10-J10 -> 650000 | J10: 123500 | K10: 773500 | L10: CRUZA | M10: N/A | N10: =IFERROR(IF(-_xlfn.DAYS(E10,M10)<0,0,-_xlfn.DAYS(E10,M10)), " - ") -> - | O10: FRANCY SALAS
A11: Factura electrónica | B11: dd0011eb4b5647395d5a5a8781955be804153b53cd90b6990c73b1dee24c124375c6d3b03add393fa3333425aacb6575 | C11: 1213609 | D11: 2091 | E11: 46055 | F11: 46055.912 | G11: 890903790 | H11: SEGUROS DE VIDA SURAMERICANA S.A | I11: =K11-J11 -> 1643587 | J11: 82179.35 | K11: 1725766.4 | L11: GESTION HUMANA | M11: 46076 | N11: =IFERROR(IF(-_xlfn.DAYS(E11,M11)<0,0,-_xlfn.DAYS(E11,M11)), " - ") -> 21 | W11: MAS 10
A12: Factura electrónica | B12: 5a59de4888820535220d847370d5c335afbffa2e042d66f739e329ffa5889cf8b5c5ff90f8603c372e8eb76eb75eafc5 | C12: 1896 | D12: SGKE | E12: 46055 | F12: 46055.783 | G12: 901068561 | H12: SUGEEK SAS | I12: =K12-J12 -> 199000 | J12: 0 | K12: 199000 | L12: TI | M12: 46076 | N12: =IFERROR(IF(-_xlfn.DAYS(E12,M12)<0,0,-_xlfn.DAYS(E12,M12)), " - ") -> 21 | O12: ALEXANDER TABORDA | T12: 46058 | U12: NO | W12: MAS 10
A13: Factura electrónica | B13: 2d8a77cc4dd5467b27f1e519d499ddf6a53bda457bb188f8f833b5fc3d06b27dbe97b53aab88224f7532382cb351cfdb | C13: 122 | D13: JA | E13: 46055 | F13: 46055.725 | G13: 15442838 | H13: GOMEZ JHON ARLEY | I13: =K13-J13 -> 1518400 | J13: 288496 | K13: 1806896 | L13: OPERACIONES | M13: 46076 | N13: =IFERROR(IF(-_xlfn.DAYS(E13,M13)<0,0,-_xlfn.DAYS(E13,M13)), " - ") -> 21 | O13: CARLOS RENDON | T13: 46058 | U13: NO | W13: MAS 10
A14: Factura electrónica | B14: 8bbfc0b04e26ba57b3b6112ae1a0d8fb7d2e56f5259a7bb3ba6d382abc982c38c4c958164530c8b5582cbdf0298d9734 | C14: 55735 | D14: FVE | E14: 46055 | F14: 46055.712 | G14: 900650486 | H14: DISTRIBUIDORA DE SOFTWARE Y MOVILIDAD S.A.S | I14: =K14-J14 -> 1936974.8 | J14: 368025.22 | K14: 2305000 | L14: TI | M14: 46076 | N14: =IFERROR(IF(-_xlfn.DAYS(E14,M14)<0,0,-_xlfn.DAYS(E14,M14)), " - ") -> 21 | O14: YENIFER PARRA | T14: 46059 | U14: NO | W14: MAS 10
A15: Factura electrónica | B15: b1f9399bfb0ecf8188513131d6732d09defba12c231cf936381ed5f9ad85aefc7bf7c6857190de9a3f1c3022885d4c36 | C15: 1288 | D15: SM | E15: 46055 | F15: 46055.703 | G15: 901561580 | H15: SUMINISTRO MATERIALES Y DOTACIONES SUMADO S.A.S | I15: =K15-J15 -> 2964947.8 | J15: 563340.08 | K15: 3528287.9 | L15: COMPRAS | M15: 46076 | N15: =IFERROR(IF(-_xlfn.DAYS(E15,M15)<0,0,-_xlfn.DAYS(E15,M15)), " - ") -> 21 | O15: YENIFER PARRA | T15: 46065 | U15: NO | W15: MAS 10
A16: Factura electrónica | B16: 44b4f27598c1cef4dd66f35816e205063021a4bff0f356b046323ff40d5059c1d11af8f529ccf18ce308316ac67b2187 | C16: 5913 | E16: 46055 | F16: 46055.913 | G16: 32150739 | H16: NATALIA ANDREA ACOSTA COLORADO | I16: =K16-J16 -> 637500 | J16: 0 | K16: 637500 | L16: GESTION HUMANA | M16: 46076 | N16: =IFERROR(IF(-_xlfn.DAYS(E16,M16)<0,0,-_xlfn.DAYS(E16,M16)), " - ") -> 21 | O16: YENIFER PARRA | T16: 46059 | U16: NO | W16: MAS 10
A17: Factura electrónica | B17: 21e25254a25bd088c4b4f00f45d867aa728f895fc3fb38cb109b7989193fdfdf1b0e9a0c95050ad921802ac7d1a73f03 | C17: 100115489 | D17: 9944 | E17: 46055 | F17: 46055.877 | G17: 800242106 | H17: SODIMAC COLOMBIA S.A. | I17: =K17-J17 -> 24900 | J17: 0 | K17: 24900 | L17: COMPRAS | M17: 46076 | N17: =IFERROR(IF(-_xlfn.DAYS(E17,M17)<0,0,-_xlfn.DAYS(E17,M17)), " - ") -> 21 | O17: YENIFER PARRA | T17: 46062 | U17: NO | W17: MAS 10
A18: Factura electrónica | B18: db3dc9aefab95f1c6cf7258be6929c762abd2eb232117f2cf2b14cf102439a556c8492290f8f729907d9f11f11692d18 | C18: 378 | D18: MD | E18: 46055 | F18: 46055.869 | G18: 900484392 | H18: Sigfrido SAS | I18: =K18-J18 -> 27859250 | J18: 5293257.5 | K18: 33152508 | L18: CONTABILIDAD | M18: 46076 | N18: =IFERROR(IF(-_xlfn.DAYS(E18,M18)<0,0,-_xlfn.DAYS(E18,M18)), " - ") -> 21 | O18: NATALIA BERNAZA | T18: 46057 | U18: NO | W18: MAS 10
A19: Factura electrónica | B19: 92df2cc88099e9c3beccdcaa90acbfcaef27114abea65267170a45cb8b562546f0e3584b339e2a229454e64b5cce3516 | C19: 1341 | D19: FE | E19: 46055 | F19: 46055.672 | G19: 901950863 | H19: INVERSIONES TORNILLOS Y MANGUERAS S.A.S | I19: =K19-J19 -> 800000 | J19: 152000 | K19: 952000 | L19: MANTENIMIENTO | M19: 46076 | N19: =IFERROR(IF(-_xlfn.DAYS(E19,M19)<0,0,-_xlfn.DAYS(E19,M19)), " - ") -> 21 | O19: YENIFER PARRA | T19: 46066 | U19: NO | W19: MAS 10
A20: Factura electrónica | B20: fdfcaa6bca603e97207781e56533a04f7ea4a6aa64b89d6a480dc28bedd3fab32e75fdaebc0bc9652eec363baf19d037 | C20: 7649 | D20: SM | E20: 46055 | F20: 46055.624 | G20: 800205419 | H20: S.M. EMPAQUES S.A.S. | I20: =K20-J20 -> 1125390 | J20: 213824.1 | K20: 1339214.1 | L20: COMPRAS | M20: 46076 | N20: =IFERROR(IF(-_xlfn.DAYS(E20,M20)<0,0,-_xlfn.DAYS(E20,M20)), " - ") -> 21 | O20: YENIFER PARRA | T20: 46059 | U20: NO | W20: MAS 10
A21: Factura electrónica | B21: b91a07ba9f007a0febf333f555ac6d42ad2c86314f70e795847690cab90f5294aa42cefb81b50dc3161d49917de499c9 | C21: 342402 | D21: FFEE | E21: 46055 | F21: 46055.653 | G21: 800049074 | H21: PAPELERIA Y SERVICIOS SAS | I21: =K21-J21 -> 486221 | J21: 73180 | K21: 559401 | L21: COMPRAS | M21: 46076 | N21: =IFERROR(IF(-_xlfn.DAYS(E21,M21)<0,0,-_xlfn.DAYS(E21,M21)), " - ") -> 21 | O21: YENIFER PARRA | T21: 46066 | U21: NO | W21: MAS 10
A22: Factura electrónica | B22: 087f005f0025cb19cce8a1ac4fbd1d038dcd8334d8ad9ddaec1ab011106da6d40dedd3f920e5d62316d3eca0c70fae65 | C22: 342328 | D22: FFEE | E22: 46055 | F22: 46055.538 | G22: 800049074 | H22: PAPELERIA Y SERVICIOS SAS | I22: =K22-J22 -> 76086 | J22: 3804 | K22: 79890 | L22: COMPRAS | M22: 46076 | N22: =IFERROR(IF(-_xlfn.DAYS(E22,M22)<0,0,-_xlfn.DAYS(E22,M22)), " - ") -> 21 | O22: YENIFER PARRA | T22: 46062 | U22: NO | W22: MAS 10
A23: Factura electrónica | B23: 6e7f4eacacccb4f4b10acc1f3f72a41fb5ab16fe1946b332a979d812e7eca6b1fdc22319194895fde0ccdc70ac9d2fd5 | C23: 5857 | D23: REST | E23: 46055 | F23: 46055.709 | G23: 890903388 | H23: CLUB UNION S.A. | I23: =K23-J23 -> 253050 | J23: 0 | K23: 253050 | L23: CAJA MENOR | N23: =IFERROR(IF(-_xlfn.DAYS(E23,M23)<0,0,-_xlfn.DAYS(E23,M23)), " - ") -> 0 | T23: 46066 | U23: N
A24: Factura electrónica | B24: 5e71acb723fc9db5e14b9372400cda1fa0b78358ce59f221f5353dbdedfe436cf7f2866d97a5338c58989dab12208492 | C24: 564006 | D24: AH | E24: 46055 | F24: 46055.374 | G24: 890800788 | H24: SUMATEC S.A.S BIC | I24: =K24-J24 -> 319550 | J24: 60715 | K24: 380265 | L24: COMPRAS | M24: 46076 | N24: =IFERROR(IF(-_xlfn.DAYS(E24,M24)<0,0,-_xlfn.DAYS(E24,M24)), " - ") -> 21 | O24: YENIFER PARRA | T24: 46059 | U24: NO | W24: MAS 10
A25: Factura electrónica | B25: 9eb29bcfc66c363017b2bb20e96b978a2798cb8dce064707a02d3a1ccb5e5663bbfb7af3571a730b0049f8fbb0d28c26 | C25: 7650 | D25: SM | E25: 46055 | F25: 46055.624 | G25: 800205419 | H25: S.M. EMPAQUES S.A.S. | I25: =K25-J25 -> 397080 | J25: 75445.2 | K25: 472525.2 | L25: COMPRAS | M25: 46076 | N25: =IFERROR(IF(-_xlfn.DAYS(E25,M25)<0,0,-_xlfn.DAYS(E25,M25)), " - ") -> 21 | O25: YENIFER PARRA | T25: 46059 | U25: NO | W25: MAS 10
A26: Factura electrónica | B26: 84c11647634126cf5dcb33fa3af5a027c669c2e8df5090b7cd418d19b0e7ce4e65e034f22d5677e4292f9280c8181146 | C26: 2711 | D26: FVE | E26: 46055 | F26: 46055.445 | G26: 900667734 | H26: TORNO PARTES S.A.S | I26: =K26-J26 -> 1120000 | J26: 212800 | K26: 1332800 | L26: MANTENIMIENTO | M26: 46076 | N26: =IFERROR(IF(-_xlfn.DAYS(E26,M26)<0,0,-_xlfn.DAYS(E26,M26)), " - ") -> 21 | O26: YENIFER PARRA | T26: 46066 | U26: NO | W26: MAS 10
A27: Factura electrónica | B27: 16c966286b1f44bf21115accef363ad564cce1ffd93b55e7f7475c236eed58254be83d6cacc94d9abd827f2f8d820c5e | C27: 151096 | D27: LA | E27: 46055 | F27: 46055.691 | G27: 811013715 | H27: LINEA ADHESIVA S.A.S. BIC. | I27: =K27-J27 -> 4110926.1 | J27: 781076.02 | K27: 4892002.2 | L27: COMPRAS | M27: 46076 | N27: =IFERROR(IF(-_xlfn.DAYS(E27,M27)<0,0,-_xlfn.DAYS(E27,M27)), " - ") -> 21 | O27: FRANCY SALAS | T27: 46071 | U27: NO | W27: MAS 10
A28: Factura electrónica | B28: ef9efb90ab44ad63f11f91bc5acf840e3ed912b2e76277b7b9c5f9aa34db343b939ed4948ae4a0910c7120d4f6d4692d | C28: 18403 | D28: INIM | E28: 46055 | F28: 46055.532 | G28: 900237741 | H28: INVERSIONES IMPRIMA SAS | I28: =K28-J28 -> 135000 | J28: 25650 | K28: 160650 | L28: COMPRAS | M28: 46076 | N28: =IFERROR(IF(-_xlfn.DAYS(E28,M28)<0,0,-_xlfn.DAYS(E28,M28)), " - ") -> 21 | O28: YENIFER PARRA | T28: 46059 | U28: NO | W28: MAS 10
A29: Factura electrónica | B29: b6ecd6a2d554e408507ed92f3544ba0328f2a6e9b4c479921f679a3019860f129b2711a2eab854f7d7a245eaba0f22f9 | C29: 18402 | D29: INIM | E29: 46055 | F29: 46055.532 | G29: 900237741 | H29: INVERSIONES IMPRIMA SAS | I29: =K29-J29 -> 150000 | J29: 28500 | K29: 178500 | L29: COMPRAS | M29: 46076 | N29: =IFERROR(IF(-_xlfn.DAYS(E29,M29)<0,0,-_xlfn.DAYS(E29,M29)), " - ") -> 21 | O29: YENIFER PARRA | T29: 46059 | U29: NO | W29: MAS 10
A30: Factura electrónica | B30: 854e29821dbde59a525562c19ae26fb765ec91bc1f2ce031a5d4c949d3614333829f9236e3ecf5da73081bf9809fd01d | C30: 21735 | D30: FE | E30: 46055 | F30: 46055.412 | G30: 900083323 | H30: AGENCIA DE INVERSIONES PROSPERAR S.A.S. | I30: =K30-J30 -> 10499723 | J30: 1774638 | K30: 12274361 | L30: CONTABILIDAD | M30: 46076 | N30: =IFERROR(IF(-_xlfn.DAYS(E30,M30)<0,0,-_xlfn.DAYS(E30,M30)), " - ") -> 21 | O30: NATALIA BERNAZA | T30: 46057 | U30: SI | W30: MAS 10
A31: Factura electrónica | B31: a64bd6a41d1f0758930e03652d4d3c895edb53f9fd8824176508d5643307ef7ce14667d46cbc98a0d64d699db8570c59 | C31: 1139 | D31: FE | E31: 46055 | F31: 46055.656 | G31: 811007030 | H31: CREACIONES POSADA & JARAMILLO S.A.S. | I31: =K31-J31 -> 2101400 | J31: 399266 | K31: 2500666 | L31: COMPRAS | M31: 46076 | N31: =IFERROR(IF(-_xlfn.DAYS(E31,M31)<0,0,-_xlfn.DAYS(E31,M31)), " - ") -> 21 | O31: YENIFER PARRA | T31: 46059 | U31: NO | W31: MAS 10
A32: Factura electrónica | B32: a7e9842e4b7784ae2a488ba3229a0ac23cb16d8fe05be8ac9e9dcb5302385561ec9cab785adcd68dcd2810b189c7ee40 | C32: 564020 | D32: AH | E32: 46055 | F32: 46055.442 | G32: 890800788 | H32: SUMATEC S.A.S BIC | I32: =K32-J32 -> 107335 | J32: 20394 | K32: 127729 | L32: COMPRAS | M32: 46076 | N32: =IFERROR(IF(-_xlfn.DAYS(E32,M32)<0,0,-_xlfn.DAYS(E32,M32)), " - ") -> 21 | O32: YENIFER PARRA | T32: 46066 | U32: NO | W32: MAS 10
A33: Factura electrónica | B33: a24682aa6bc32ab3af1bebf7f5a75b80ae2b852971ae01c690382f2ce4b74a9f911fea246686625e1f8072bf88cda2bc | C33: 104244 | D33: FAE | E33: 46055 | F33: 46055.503 | G33: 830120839 | H33: MULTISUMINISTROS INDUSTRIALES S A S | I33: =K33-J33 -> 78668 | J33: 14947 | K33: 93615 | L33: COMPRAS | M33: 46076 | N33: =IFERROR(IF(-_xlfn.DAYS(E33,M33)<0,0,-_xlfn.DAYS(E33,M33)), " - ") -> 21 | O33: YENIFER PARRA | T33: 46059 | U33: NO | W33: MAS 10
A34: Factura electrónica | B34: b93fb3bde363cf1b437d6cca3855c1858c39f2aca7a020321b5e6a34224054e551e008b72af5eb8cf1a20f9088e5cc64 | C34: 342331 | D34: FFEE | E34: 46055 | F34: 46055.538 | G34: 800049074 | H34: PAPELERIA Y SERVICIOS SAS | I34: =K34-J34 -> 13335 | J34: 2534 | K34: 15869 | L34: COMPRAS | M34: 46076 | N34: =IFERROR(IF(-_xlfn.DAYS(E34,M34)<0,0,-_xlfn.DAYS(E34,M34)), " - ") -> 21 | O34: YENIFER PARRA | T34: 46062 | U34: NO | W34: MAS 10
A35: Factura electrónica | B35: 937a0f8a3bc8ffad396c0609ff62a5f79d4a9d021962f6fb19e0e950e117ba47927c86cebb4f997211ba03ac2f9ccd03 | C35: 21627 | D35: FE | E35: 46055 | F35: 46055.386 | G35: 900083323 | H35: AGENCIA DE INVERSIONES PROSPERAR S.A.S. | I35: =K35-J35 -> 9632900 | J35: 1830251 | K35: 11463151 | L35: CONTABILIDAD | M35: 46056 | N35: =IFERROR(IF(-_xlfn.DAYS(E35,M35)<0,0,-_xlfn.DAYS(E35,M35)), " - ") -> 1 | O35: NATALIA BERNAZA | T35: 46057 | U35: SI | W35: 0 A 5
A36: Factura electrónica | B36: 1d8dca1213d161c1f724ab3bacb17a9b096d56a459af52673b45e8104db2fa8a38d16dfb404621f1555f151472acf044 | C36: 564003 | D36: AH | E36: 46055 | F36: 46055.368 | G36: 890800788 | H36: SUMATEC S.A.S BIC | I36: =K36-J36 -> 276000 | J36: 52440 | K36: 328440 | L36: COMPRAS | M36: 46057 | N36: =IFERROR(IF(-_xlfn.DAYS(E36,M36)<0,0,-_xlfn.DAYS(E36,M36)), " - ") -> 2 | O36: YENIFER PARRA | T36: 46062 | U36: NO | W36: 0 A 5
A37: Factura electrónica | B37: d4e5bec6099b844cbccba0db6c598872f3bb16fa53416266716c3990971e7f65a3b3aac2d42a81a1b2cd0a9acb6f583c | C37: 91852 | D37: 1PQE | E37: 46055 | F37: 46055.712 | G37: 900125852 | H37: CI SAN FERNANDO PLAZA PH. | I37: =K37-J37 -> 19327.39 | J37: 3672.61 | K37: 23000 | L37: CAJA MENOR | N37: =IFERROR(IF(-_xlfn.DAYS(E37,M37)<0,0,-_xlfn.DAYS(E37,M37)), " - ") -> 0
A38: Factura electrónica | B38: a9c4e39224d0454af3be7d4f8157de3803f7e3be73e4cc96003c1be8b632f9e5f49f566d8150b12e4c86ecbfcdc277fd | C38: 1340 | D38: FE | E38: 46055 | F38: 46055.665 | G38: 901950863 | H38: INVERSIONES TORNILLOS Y MANGUERAS S.A.S | I38: =K38-J38 -> 72000 | J38: 13680 | K38: 85680 | L38: MANTENIMIENTO | M38: 46057 | N38: =IFERROR(IF(-_xlfn.DAYS(E38,M38)<0,0,-_xlfn.DAYS(E38,M38)), " - ") -> 2 | O38: YENIFER PARRA | T38: 46066 | U38: NO | W38: 0 A 5
A39: Factura electrónica | B39: 2a6c47bc6d7641ce1298190edfc7ac84febd05a6a8785a25fef8fb1b2c317505244320f61f1262b158dcd9547ca9da9d | C39: 7648 | D39: SM | E39: 46055 | F39: 46055.62 | G39: 800205419 | H39: S.M. EMPAQUES S.A.S. | I39: =K39-J39 -> 375130 | J39: 71274.7 | K39: 446404.7 | L39: COMPRAS | M39: 46057 | N39: =IFERROR(IF(-_xlfn.DAYS(E39,M39)<0,0,-_xlfn.DAYS(E39,M39)), " - ") -> 2 | O39: YENIFER PARRA | T39: 46059 | U39: NO | W39: 0 A 5
A40: Factura electrónica | B40: 3ec7c0fdedf9fb927d884e20aac526c929606e21e3bba11ceaadfc4acb7c7bbea24e4a6dd57132e80b9fba797a35dabe | C40: 2712 | D40: FVE | E40: 46055 | F40: 46055.459 | G40: 900667734 | H40: TORNO PARTES S.A.S | I40: =K40-J40 -> 178680 | J40: 33949.2 | K40: 212629.2 | L40: MANTENIMIENTO | M40: 46057 | N40: =IFERROR(IF(-_xlfn.DAYS(E40,M40)<0,0,-_xlfn.DAYS(E40,M40)), " - ") -> 2 | O40: YENIFER PARRA | T40: 46066 | U40: NO | W40: 0 A 5
...

Sheet MARZO
B1: CUFE/CUDE | C1: Folio | D1: Prefijo | E1: Fecha Emisión | F1: Fecha Recepción | G1: NIT | H1: Nombre Emisor | I1: Subtotal | J1: IVA | K1: Total | L1: Responsable | M1: FECHA DE ENTREGA | N1: DÍAS DE ENTREGA A CONTABILIDAD | O1: QUIEN ENTREGA | P1: NOMBRE A QUIEN SE DEVUELVE | Q1: FECHA DEVOLUCION | R1: REINTEGRO | S1: RANGO DE ENTREGA A TESORERIA DIAS | T1: FECHA ENTREGA TESORERIA | U1: REQUIERE FIRMA DE GERENCIA | V1: FIRMADAS | W1: RANGO DÍAS DE ENTREGA | X1: MES DEL SERVICIO
A2: Factura electrónica | B2: 6e1893a7f6ca082c1b22dd31c7963fa37f52cf635ef77130a325891a0742c51fd33b4b469f5d1286b6fae2635841075e | C2: 3900 | D2: RIND | E2: 46082 | F2: 46082.689 | G2: 901609691 | H2: RINDEGASTOS COLOMBIA S.A.S. | I2: =K2-J2 -> 742400 | J2: 141056 | K2: 883456 | L2: CONTABILIDAD | M2: 46084 | N2: =IFERROR(IF(-_xlfn.DAYS(E2,M2)<0,0,-_xlfn.DAYS(E2,M2)), " - ") -> 2 | O2: NATALIA BERNAZA | T2: 46085 | U2: NO | W2: 0 A 5
A3: Factura electrónica | B3: f166054df051ee247b3b6dfae09e7a85ace4193591c228425ef96fabe0ab147f7ea10d79d351b27df5bc946e82d5905d | C3: 292542251 | D3: 3 | E3: 46082 | F3: 46086.879 | G3: 800153993 | H3: COMUNICACION CELULAR S A COMCEL S A | I3: =K3-J3 -> 1967321 | J3: 44197.99 | K3: 2011519 | L3: TI | M3: 46097 | N3: =IFERROR(IF(-_xlfn.DAYS(E3,M3)<0,0,-_xlfn.DAYS(E3,M3)), " - ") -> 15 | O3: JAIME GARCIA | T3: 46099 | U3: NO | W3: MAS DE 10
A4: Factura electrónica | B4: e2a472c6b736117ab460068855dd61885fe01f72645739bf9c300bb14ec2b29517c0ca4ca3f0e0825c0cd8afd5f9b1af | C4: 41146 | D4: AEZY | E4: 46082 | F4: 46082.335 | G4: 900610585 | H4: Easytaxi Colombia SAS | I4: =K4-J4 -> 2793209 | J4: 73201 | K4: 2866410 | L4: COMPRAS | M4: 46083 | N4: =IFERROR(IF(-_xlfn.DAYS(E4,M4)<0,0,-_xlfn.DAYS(E4,M4)), " - ") -> 1 | O4: FRANCY SALAS | T4: 46086 | U4: NO | W4: 0 A 5
A5: Factura electrónica | B5: e1c5da3d561d703cd18cccc12e450474712a5dd55badff33633a96edad1a582168613ca775df12f49224c4b1adee664a | C5: 657001 | D5: ECCO | E5: 46083 | F5: 46083.834 | G5: 811009788 | H5: DISTRACOM S.A. | I5: =K5-J5 -> 111368 | J5: 0 | K5: 111368 | L5: COMPRAS | M5: 46086 | N5: =IFERROR(IF(-_xlfn.DAYS(E5,M5)<0,0,-_xlfn.DAYS(E5,M5)), " - ") -> 3 | O5: FRANCY SALAS | T5: 46087 | W5: 0 A 5
A6: Factura electrónica | B6: 4ce8e965d2ef76e7155ed377a6e69559b716067475957f760e01b642d5d3ad38c158941749b1d34a9ace50e20cc794e1 | C6: 18 | D6: FVE | E6: 46083 | F6: 46083.588 | G6: 902020620 | H6: REDECILLAS POLI SAS | I6: =K6-J6 -> 144450 | J6: 27445.5 | K6: 171895.5 | L6: COMPRAS | M6: 46097 | N6: =IFERROR(IF(-_xlfn.DAYS(E6,M6)<0,0,-_xlfn.DAYS(E6,M6)), " - ") -> 14 | O6: FRANCY SALAS | T6: 46098 | U6: NO | W6: MAS DE 10
A7: Factura electrónica | B7: 7c5dc27a64658decb9aab7b66087c5d7f4d9553fd4e8520450a2fc5a3dc5f5068ec657328686dc6717723fd22470faaf | C7: 244 | D7: ESAB | E7: 46083 | F7: 46083.994 | G7: 901200557 | H7: AFAT SAS | I7: =K7-J7 -> 36050.42 | J7: 6849.58 | K7: 42900 | L7: CAJA MENOR | N7: =IFERROR(IF(-_xlfn.DAYS(E7,M7)<0,0,-_xlfn.DAYS(E7,M7)), " - ") -> 0
A8: Factura electrónica | B8: 465e5db436a1b6cc640e9df3830635796e7620d1bc23458f346b836eb9da499830a8e7c2c9ec2e0faf8b41dfc9aaa4eb | C8: 6457 | E8: 46083 | F8: 46083.915 | G8: 32150739 | H8: NATALIA ANDREA ACOSTA COLORADO | I8: =K8-J8 -> 707400 | J8: 0 | K8: 707400 | L8: GESTION HUMANA | M8: 46087 | N8: =IFERROR(IF(-_xlfn.DAYS(E8,M8)<0,0,-_xlfn.DAYS(E8,M8)), " - ") -> 4 | O8: FRANCY SALAS | T8: 46091 | U8: NO | W8: 0 A 5
A9: Factura electrónica | B9: 5a24050e65952960150ac5d122c6f91b464036e090878d202f3430c1bbcbf237803f094f4421d3a5ef51730176e28a79 | C9: 51569 | D9: 321F | E9: 46083 | F9: 46083.757 | G9: 860533413 | H9: IRCC SAS | I9: =K9-J9 -> 30900 | J9: 0 | K9: 30900 | L9: CAJA MENOR | N9: =IFERROR(IF(-_xlfn.DAYS(E9,M9)<0,0,-_xlfn.DAYS(E9,M9)), " - ") -> 0
A10: Factura electrónica | B10: 7b3fd961227b66183d04e55ce2d52b37ef311aab02d5dbe8f63f4b87c378bfde922428c624efd6e59cabaec74b3579a9 | C10: 51568 | D10: 321F | E10: 46083 | F10: 46083.756 | G10: 860533413 | H10: IRCC SAS | I10: =K10-J10 -> 33900 | J10: 0 | K10: 33900 | L10: CAJA MENOR | N10: =IFERROR(IF(-_xlfn.DAYS(E10,M10)<0,0,-_xlfn.DAYS(E10,M10)), " - ") -> 0
A11: Factura electrónica | B11: 71f36e3301797da4a504eec51cc92fe3c382a663b5f5856133dfaf4f500ff45f4e908fed77cb5e1e2373d3595607e5e8 | C11: 51567 | D11: 321F | E11: 46083 | F11: 46083.754 | G11: 860533413 | H11: IRCC SAS | I11: =K11-J11 -> 35900 | J11: 0 | K11: 35900 | L11: CAJA MENOR | N11: =IFERROR(IF(-_xlfn.DAYS(E11,M11)<0,0,-_xlfn.DAYS(E11,M11)), " - ") -> 0
A12: Factura electrónica | B12: 93e70c1c1082515055f57bcf7f0bc55e36c6a65f1819d68b96e8baeba726273f4ce47077f7233ce305dacccbc64525f4 | C12: 5025 | D12: FEIT | E12: 46083 | F12: 46083.74 | G12: 901042685 | H12: ITTERACTIVO S.A.S. | I12: =K12-J12 -> 1593963 | J12: 0 | K12: 1593963 | L12: TI | M12: 46084 | N12: =IFERROR(IF(-_xlfn.DAYS(E12,M12)<0,0,-_xlfn.DAYS(E12,M12)), " - ") -> 1 | O12: JACOBO GARCIA | T12: 46087 | W12: 0 A 5
A13: Factura electrónica | B13: bff9d38813428cec2887ad76b5058c2f80b72b0c149594702ba9fb172d5c75d7bf62a79e6ee22c3b40ce1eef4a02ab0b | C13: 19773 | D13: FE | E13: 46083 | F13: 46083.673 | G13: 890903388 | H13: CLUB UNION SA | I13: =K13-J13 -> 1699072 | J13: 322823.68 | K13: 2021895.7 | L13: CONTABILIDAD | M13: 46084 | N13: =IFERROR(IF(-_xlfn.DAYS(E13,M13)<0,0,-_xlfn.DAYS(E13,M13)), " - ") -> 1 | O13: NATALIA BERNAZA | T13: 46085 | U13: NO | W13: 0 A 5
A14: Factura electrónica | B14: bff40a367d86a9ed600d35b908a2c2fef7f5ea52f3cb31c29d6cb291963e2ae41eb5d75e51057cd581aefd945f148379 | C14: 18982 | D14: INIM | E14: 46083 | F14: 46083.649 | G14: 900237741 | H14: INVERSIONES IMPRIMA SAS | I14: =K14-J14 -> 110000 | J14: 20900 | K14: 130900 | L14: COMPRAS | M14: 46084 | N14: =IFERROR(IF(-_xlfn.DAYS(E14,M14)<0,0,-_xlfn.DAYS(E14,M14)), " - ") -> 1 | O14: FRANCY SALAS | T14: 46086 | W14: 0 A 5
A15: Factura electrónica | B15: 69b894515016dd0e63c6712d1a5650c714fcdecf39847f7ebe57b10ff99185b45d450799857ffad43af781994b947a47 | C15: 18981 | D15: INIM | E15: 46083 | F15: 46083.648 | G15: 900237741 | H15: INVERSIONES IMPRIMA SAS | I15: =K15-J15 -> 82500 | J15: 15675 | K15: 98175 | L15: COMPRAS | M15: 46084 | N15: =IFERROR(IF(-_xlfn.DAYS(E15,M15)<0,0,-_xlfn.DAYS(E15,M15)), " - ") -> 1 | O15: FRANCY SALAS | T15: 46086 | U15: NO | W15: 0 A 5
A16: Factura electrónica | B16: 2311d5d462e93d5d6f62f30e9d33e07be610ee4d5f01fdcb826c0ea7e6e20a55ca6503441dd5f6c24b0bf36d6c6e82b0 | C16: 18980 | D16: INIM | E16: 46083 | F16: 46083.648 | G16: 900237741 | H16: INVERSIONES IMPRIMA SAS | I16: =K16-J16 -> 270000 | J16: 51300 | K16: 321300 | L16: COMPRAS | M16: 46084 | N16: =IFERROR(IF(-_xlfn.DAYS(E16,M16)<0,0,-_xlfn.DAYS(E16,M16)), " - ") -> 1 | O16: FRANCY SALAS | T16: 46086 | U16: NO | W16: 0 A 5
A17: Factura electrónica | B17: bf60885df9014d1bdabd6fceae2117c9b49a25a5a2453e767290f7a0880d467cc111b2b4b268bfa1489ff079dfaaf965 | C17: 12671 | D17: FE | E17: 46083 | F17: 46083.617 | G17: 900420442 | H17: INSTRUMENTOS PARTES S.A.S. | I17: =K17-J17 -> 581434 | J17: 110472.46 | K17: 691906.46 | L17: MANTENIMIENTO | M17: 46085 | N17: =IFERROR(IF(-_xlfn.DAYS(E17,M17)<0,0,-_xlfn.DAYS(E17,M17)), " - ") -> 2 | O17: FRANCY SALAS | T17: 46086 | U17: NO | W17: 0 A 5
A18: Factura electrónica | B18: ec9a72095ec16ccfc7be79fb72e17a23e1046ff5d8b832742b21f411645d93e78f79d9171d9582e278d0de690fa47fb8 | C18: 12670 | D18: FE | E18: 46083 | F18: 46083.609 | G18: 900420442 | H18: INSTRUMENTOS PARTES S.A.S. | I18: =K18-J18 -> 3537600 | J18: 672144 | K18: 4209744 | L18: MANTENIMIENTO | M18: 46085 | N18: =IFERROR(IF(-_xlfn.DAYS(E18,M18)<0,0,-_xlfn.DAYS(E18,M18)), " - ") -> 2 | O18: FRANCY SALAS | T18: 46094 | U18: NO | W18: 0 A 5
A19: Factura electrónica | B19: d67513e7638989d30665b71905e17ad219d13818862cd768c6b12bbcb12f3c11f1d61254fdea623072ddab9a18753507 | C19: 12669 | D19: FE | E19: 46083 | F19: 46083.609 | G19: 900420442 | H19: INSTRUMENTOS PARTES S.A.S. | I19: =K19-J19 -> 177100 | J19: 33649 | K19: 210749 | L19: MANTENIMIENTO | M19: 46085 | N19: =IFERROR(IF(-_xlfn.DAYS(E19,M19)<0,0,-_xlfn.DAYS(E19,M19)), " - ") -> 2 | O19: FRANCY SALAS | T19: 46086 | U19: NO | W19: 0 A 5
A20: Factura electrónica | B20: e19b861ae843069572105fcfb10eb09d7085c726a5101a781a88bbc02a05723b5173330311b96239bb236e6163acb7c3 | C20: 34140348 | D20: FE09 | E20: 46083 | F20: 46083.603 | G20: 809002625 | H20: INTERNACIONAL DE ELECTRICOS S.A.S | I20: =K20-J20 -> 1014900 | J20: 192831 | K20: 1207731 | L20: MANTENIMIENTO | M20: 46086 | N20: =IFERROR(IF(-_xlfn.DAYS(E20,M20)<0,0,-_xlfn.DAYS(E20,M20)), " - ") -> 3 | O20: FRANCY SALAS | T20: 46094 | U20: NO | W20: 0 A 5
A21: Factura electrónica | B21: c54a54a4848825ba3df25f9207314a4a1e856e5386c32de996e17f9aac9146ec8b8230108fe68f322a5ae0100901c2b8 | C21: 726599 | D21: FMED | E21: 46083 | F21: 46083.598 | G21: 890915475 | H21: EMPAQUETADURAS Y EMPAQUES S.A. | I21: =K21-J21 -> 192572 | J21: 36588.68 | K21: 229160.68 | L21: COMPRAS | M21: 46084 | N21: =IFERROR(IF(-_xlfn.DAYS(E21,M21)<0,0,-_xlfn.DAYS(E21,M21)), " - ") -> 1 | O21: FRANCY SALAS | T21: 46086 | U21: NO | W21: 0 A 5
A22: Factura electrónica | B22: d73b16e3a7df071193bc785d282c8a0c20be8d5540abacd0945b7c709fe9bcfd8b97f8ffa5156a9a03de1d26ecaac18f | C22: 346448 | D22: FFEE | E22: 46083 | F22: 46083.555 | G22: 800049074 | H22: PAPELERIA Y SERVICIOS SAS | I22: =K22-J22 -> 1100637 | J22: 187817 | K22: 1288454 | L22: COMPRAS | M22: 46087 | N22: =IFERROR(IF(-_xlfn.DAYS(E22,M22)<0,0,-_xlfn.DAYS(E22,M22)), " - ") -> 4 | O22: FRANCY SALAS | T22: 46094 | U22: NO | W22: 0 A 5
A23: Factura electrónica | B23: c804b968c2af3fbb7f73a93d1db0ec85e17eea1355e8d5fd7a9a30ad7a5fb9fcc85a44186072ea1e553931dff38459e5 | C23: 346483 | D23: FFEE | E23: 46083 | F23: 46083.556 | G23: 800049074 | H23: PAPELERIA Y SERVICIOS SAS | I23: =K23-J23 -> 81286 | J23: 4792 | K23: 86078 | L23: COMPRAS | M23: 46085 | N23: =IFERROR(IF(-_xlfn.DAYS(E23,M23)<0,0,-_xlfn.DAYS(E23,M23)), " - ") -> 2 | O23: FRANCY SALAS | T23: 46086 | U23: NO | W23: 0 A 5
A24: Factura electrónica | B24: 2faf2c03201a289199c6774d307de871f936b62645cd4ba118948971ed5bccd930269890f7a6e0cdf2eb93897492be3b | C24: 22134 | D24: FE | E24: 46083 | F24: 46083.525 | G24: 900083323 | H24: AGENCIA DE INVERSIONES PROSPERAR S.A.S. | I24: =K24-J24 -> 10707388 | J24: 1848510 | K24: 12555898 | L24: CONTABILIDAD | M24: 46084 | N24: =IFERROR(IF(-_xlfn.DAYS(E24,M24)<0,0,-_xlfn.DAYS(E24,M24)), " - ") -> 1 | O24: NATALIA BERNAZA | T24: 46085 | U24: NO | W24: 0 A 5
A25: Factura electrónica | B25: ff94655843b56f3fe5f5e558eba296ab12473487a6cb22e076d75e8ec12ad3fa266072f225f598df553ff68122bec015 | C25: 22135 | D25: FE | E25: 46083 | F25: 46083.525 | G25: 900083323 | H25: AGENCIA DE INVERSIONES PROSPERAR S.A.S. | I25: =K25-J25 -> 10707388 | J25: 1848510 | K25: 12555898 | L25: CONTABILIDAD | M25: 46084 | N25: =IFERROR(IF(-_xlfn.DAYS(E25,M25)<0,0,-_xlfn.DAYS(E25,M25)), " - ") -> 1 | O25: NATALIA BERNAZA | T25: 46085 | U25: NO | W25: 0 A 5
A26: Factura electrónica | B26: 4129f246ddab8f2034bda4b450328661e01dfe6c1d686f026230dd188c1b065cf7c34dace7ff7c8988e852bb0d872bbb | C26: 22069 | D26: FE | E26: 46083 | F26: 46083.508 | G26: 900083323 | H26: AGENCIA DE INVERSIONES PROSPERAR S.A.S. | I26: =K26-J26 -> 9007221 | J26: 1540482 | K26: 10547703 | L26: CONTABILIDAD | M26: 46084 | N26: =IFERROR(IF(-_xlfn.DAYS(E26,M26)<0,0,-_xlfn.DAYS(E26,M26)), " - ") -> 1 | O26: NATALIA BERNAZA | T26: 46085 | U26: NO | W26: 0 A 5
... A34: Factura electrónica | B34: e8f3d8f368cdbf39124e6070a13cc20fc1977b4c881bf530d0e9482231c1ac85bd221a46b8c4c2949544b684a9928d5d | C34: 22025 | D34: FE | E34: 46083 | F34: 46083.497 | G34: 900083323 | H34: AGENCIA DE INVERSIONES PROSPERAR S.A.S. | I34: =K34-J34 -> 8961500 | J34: 1702685 | K34: 10664185 | L34: CONTABILIDAD | M34: 46084 | N34: =IFERROR(IF(-_xlfn.DAYS(E34,M34)<0,0,-_xlfn.DAYS(E34,M34)), " - ") -> 1 | O34: NATALIA BERNAZA | T34: 46085 | U34: NO | W34: 0 A 5
A35: Factura electrónica | B35: 8adcc8242e738cd066b82e27efe20824cd88b9f5e79e2adf28df6eec32bb31b096bf961d2a2d989d98046d267f6d96b6 | C35: 3844 | D35: EC | E35: 46083 | F35: 46083.48 | G35: 900284447 | H35: COMERCIALIZADORA VIBO SAS | I35: =K35-J35 -> 519749 | J35: 98752.31 | K35: 618501.31 | L35: RECHAZO | M35: N/A | N35: =IFERROR(IF(-_xlfn.DAYS(E35,M35)<0,0,-_xlfn.DAYS(E35,M35)), " - ") -> - | O35: FRANCY SALAS
A36: Factura electrónica | B36: 9c18641be68d54bc9a565ea87bb1782f613fba3aa3375ed89f9117d20bf8e7a45db428f551ca2ef63efabd0af8370e72 | C36: 1491 | D36: FE | E36: 46083 | F36: 46083.493 | G36: 901950863 | H36: INVERSIONES TORNILLOS Y MANGUERAS S.A.S | I36: =K36-J36 -> 369500 | J36: 70205 | K36: 439705 | L36: MANTENIMIENTO | M36: 46085 | N36: =IFERROR(IF(-_xlfn.DAYS(E36,M36)<0,0,-_xlfn.DAYS(E36,M36)), " - ") -> 2 | O36: FRANCY SALAS | T36: 46094 | U36: NO | W36: 0 A 5
A37: Factura electrónica | B37: 1ae365ae67d46440926616c0731486c0b7f648949cf8603f1764d3980e10a3a36e05ea1a0a8b0987ffe3c865f5b9a1bd | C37: 1490 | D37: FE | E37: 46083 | F37: 46083.485 | G37: 901950863 | H37: INVERSIONES TORNILLOS Y MANGUERAS S.A.S | I37: =K37-J37 -> 79200 | J37: 15048 | K37: 94248 | L37: MANTENIMIENTO | M37: 46085 | N37: =IFERROR(IF(-_xlfn.DAYS(E37,M37)<0,0,-_xlfn.DAYS(E37,M37)), " - ") -> 2 | O37: FRANCY SALAS | T37: 46094 | U37: NO | W37: 0 A 5
A38: Factura electrónica | B38: fb4596aaf24da540d022c5e17fb87a86f4fefcf939cfb25559f9dfe602d05e5f233bfe66a427df921953f9f64fb49f4d | C38: 1333 | D38: SM | E38: 46083 | F38: 46083.476 | G38: 901561580 | H38: SUMINISTRO MATERIALES Y DOTACIONES SUMADO S.A.S | I38: =K38-J38 -> 1710000 | J38: 324900 | K38: 2034900 | L38: COMPRAS | M38: 46090 | N38: =IFERROR(IF(-_xlfn.DAYS(E38,M38)<0,0,-_xlfn.DAYS(E38,M38)), " - ") -> 7 | O38: FRANCY SALAS | T38: 46094 | U38: NO | W38: 6 A 10
A39: Factura electrónica | B39: 1421a0ce56943af79799f5e407d59fab51cd301463079cccba3147352d9831ac8cfe2f04f71d4ceb0d456d83975511f5 | C39: 8184 | E39: 46083 | F39: 46083.657 | G39: 901360705 | H39: DELTA TAGS SAS | I39: =K39-J39 -> 647500 | J39: 123025 | K39: 770525 | L39: COMPRAS | M39: 46087 | N39: =IFERROR(IF(-_xlfn.DAYS(E39,M39)<0,0,-_xlfn.DAYS(E39,M39)), " - ") -> 4 | O39: FRANCY SALAS | T39: 46094 | U39: NO | W39: 0 A 5
A40: Factura electrónica | B40: b24e55eb153dd80c05b7ef91c7ae431cf3d20891d1aa9f840e2953d465fe871a444b59475434bff57948b519d4dc025b | C40: 8183 | E40: 46083 | F40: 46083.65 | G40: 901360705 | H40: DELTA TAGS SAS | I40: =K40-J40 -> 649610 | J40: 123425.9 | K40: 773035.9 | L40: COMPRAS | M40: 46091 | N40: =IFERROR(IF(-_xlfn.DAYS(E40,M40)<0,0,-_xlfn.DAYS(E40,M40)), " - ") -> 8 | O40: FRANCY SALAS | T40: 46094 | U40: NO | W40: 6 A 10
A41: Factura electrónica | B41: bee55bc3d31ceef8631c9f8393f81f359939a0e08ae99ba78f68ad13be6e24d71e5d4e334562d05139ddc2df6b3afe5f | C41: 8182 | E41: 46083 | F41: 46083.47 | G41: 901360705 | H41: DELTA TAGS SAS | I41: =K41-J41 -> 14400 | J41: 2736 | K41: 17136 | L41: COMPRAS | M41: 46084 | N41: =IFERROR(IF(-_xlfn.DAYS(E41,M41)<0,0,-_xlfn.DAYS(E41,M41)), " - ") -> 1 | O41: FRANCY SALAS | T41: 46086 | U41: NO | W41: 0 A 5
A42: Factura electrónica | B42: bc431dfe205c5b2ddc8e89438cf9951517997c34ded2db4b0a39999934d7b5b9af868a5827a6f2f53cd9671573e06e29 | C42: 1488 | D42: FE | E42: 46083 | F42: 46083.468 | G42: 901950863 | H42: INVERSIONES TORNILLOS Y MANGUERAS S.A.S | I42: =K42-J42 -> 900000 | J42: 171000 | K42: 1071000 | L42: MANTENIMIENTO | M42: 46085 | N42: =IFERROR(IF(-_xlfn.DAYS(E42,M42)<0,0,-_xlfn.DAYS(E42,M42)), " - ") -> 2 | O42: FRANCY SALAS | T42: 46094 | U42: NO | W42: 0 A 5
A43: Factura electrónica | B43: 2cd7b8b55a61576178ae6728290c63a9d23acfac8b5795fcb0fc4c0b46bc255253358125fcf6f552734d9ba2df85892c | C43: 56416 | D43: FVE | E43: 46083 | F43: 46083.457 | G43: 900650486 | H43: DISTRIBUIDORA DE SOFTWARE Y MOVILIDAD S.A.S | I43: =K43-J43 -> 890000 | J43: 0 | K43: 890000 | L43: TI | M43: 46085 | N43: =IFERROR(IF(-_xlfn.DAYS(E43,M43)<0,0,-_xlfn.DAYS(E43,M43)), " - ") -> 2 | O43: FRANCY SALAS | T43: 46086 | U43: NO | W43: 0 A 5
A44: Factura electrónica | B44: 1c6c1cdb280e8210b50e7b3399a8a2e23c72250649a5e853a360415755899f07110f0da6b52f86085460f280b1abaeea | C44: 94937 | D44: ES | E44: 46083 | F44: 46083.439 | G44: 800128989 | H44: GUIMAR SEGURIDAD INDUSTRIAL S.A.S | I44: =K44-J44 -> 163345 | J44: 31035.55 | K44: 194380.55 | L44: COMPRAS | M44: 46084 | N44: =IFERROR(IF(-_xlfn.DAYS(E44,M44)<0,0,-_xlfn.DAYS(E44,M44)), " - ") -> 1 | O44: FRANCY SALAS | T44: 46086 | U44: NO | W44: 0 A 5
A45: Factura electrónica | B45: 085a013b624ca1f0ecb46cf6463e76f02d81dcc3ba39577e67b5f9d78d22a52e9f9e8b432a17c90137b0fdbbf57a9636 | C45: 101168 | D45: FM | E45: 46083 | F45: 46083.435 | G45: 890929497 | H45: MAPER S.A.S | I45: =K45-J45 -> 186110 | J45: 35361 | K45: 221471 | L45: MANTENIMIENTO | M45: 46087 | N45: =IFERROR(IF(-_xlfn.DAYS(E45,M45)<0,0,-_xlfn.DAYS(E45,M45)), " - ") -> 4 | O45: FRANCY SALAS | T45: 46094 | U45: NO | W45: 0 A 5
A46: Factura electrónica | B46: 4e0886e9ad6cd99ea7c5a9299ee0fc582db575973deb5f710772321541e3dbaf704ffe67764482926dc299b36abc8d9d | C46: 474 | D46: FE | E46: 46083 | F46: 46083.654 | G46: 900566277 | H46: Mi Cuento S.A.S | I46: =K46-J46 -> 9900000 | J46: 1881000 | K46: 11781000 | L46: COMPRAS | M46: 46097 | N46: =IFERROR(IF(-_xlfn.DAYS(E46,M46)<0,0,-_xlfn.DAYS(E46,M46)), " - ") -> 14 | O46: FRANCY SALAS | T46: 46098 | U46: NO | W46: MAS DE 10
A47: Factura electrónica | B47: 2be4699300c59182747afddc44c65080922a04558badbde8d3104a4aca9767b46ee73e5245adf43affcdd9b8f87508f4 | C47: 62066 | D47: 22T | E47: 46083 | F47: 46083.644 | G47: 860509514 | H47: AUTOGERMANA S A S | I47: =K47-J47 -> 84033.61 | J47: 15966.39 | K47: 100000 | L47: CAJA MENOR | N47: =IFERROR(IF(-_xlfn.DAYS(E47,M47)<0,0,-_xlfn.DAYS(E47,M47)), " - ") -> 0
...

Sheet Indicadores.
A1: FECHA DE ENTREGA | B1: (Varios elementos) | J1: FECHA DE ENTREGA | K1: (en blanco)
A2: MES | B2: MARZO | J2: MES | K2: MARZO
A4: Cuenta de Folio | B4: Etiquetas de columna | J4: Etiquetas de fila | K4: Cuenta de Folio
A5: Etiquetas de fila | B5: 0 A 5 | C5: 6 a 10 | D5: MAS DE 10 | E5: Total general | J5: COMPRAS | K5: 1
A6: BIENESTAR | B6: 3 | E6: 3 | J6: GESTION HUMANA | K6: 3
A7: CALIDAD | B7: 12 | E7: 12 | J7: MANTENIMIENTO | K7: 4
A8: COMERCIAL | C8: 1 | D8: 1 | E8: 2 | J8: NOMINA | K8: 4
A9: COMPRAS | B9: 266 | C9: 29 | D9: 7 | E9: 302 | J9: OPERACIONES | K9: 13
A10: CONTABILIDAD | B10: 33 | E10: 33 | J10: Total general | K10: 25
A11: FINANCIERA | B11: 1 | C11: 1 | D11: 1 | E11: 3
A12: GERENCIA | B12: 1 | C12: 1 | D12: 1 | E12: 3
A13: GESTION HUMANA | B13: 19 | C13: 5 | D13: 1 | E13: 25
A14: MANTENIMIENTO | B14: 101 | C14: 38 | D14: 5 | E14: 144
A15: NOMINA | B15: 11 | C15: 6 | D15: 3 | E15: 20
A16: OPERACIONES | B16: 24 | C16: 5 | D16: 3 | E16: 32
A17: SSTA | B17: 8 | C17: 3 | E17: 11
A18: TI | B18: 25 | C18: 6 | D18: 4 | E18: 35
A19: Total general | B19: 504 | C19: 95 | D19: 26 | E19: 625
B21: =(504*100%)/625 -> 0.8064 | C21: =(121*100%)/625 -> 0.1936
D24: A tiempo | E24: Por fuera del tiempo
A26: Facturas entregadas 30/03/2026 | B26: 625 | D26: 504 | E26: 121
A27: Facturas de Caja Menor | B27: 137
A28: Facturas rechazadas | B28: 56
A29: Pendientes por entregar | B29: 25 | D29: 22 | E29: =B29-D29 -> 3

Sheet Hoja1
A1: FECHA DE ENTREGA | B1: (Varios elementos) | I1: MES | J1: ABRIL
A2: MES | B2: ABRIL | I2: FECHA DE ENTREGA | J2: (en blanco)
A4: Cuenta de Folio | B4: Etiquetas de columna | I4: Etiquetas de fila | J4: Cuenta de Folio
A5: Etiquetas de fila | B5: 0 A 5 | C5: 6 a 10 | D5: Más de 10 | E5: Total general | I5: CALIDAD | J5: 2
A6: BIENESTAR | B6: 1 | E6: 1 | I6: COMPRAS | J6: 45
A7: COMPRAS | B7: 115 | C7: 12 | D7: 18 | E7: 145 | I7: FINANCIERA | J7: 1
A8: CONTABILIDAD | B8: 24 | D8: 2 | E8: 26 | I8: GESTION HUMANA | J8: 3
A9: FINANCIERA | B9: 2 | C9: 1 | E9: 3 | I9: MANTENIMIENTO | J9: 23
A10: GERENCIA | B10: 1 | E10: 1 | I10: NOMINA | J10: 2
A11: GESTION HUMANA | B11: 6 | C11: 2 | E11: 8 | I11: OPERACIONES | J11: 4
A12: MANTENIMIENTO | B12: 16 | C12: 6 | D12: 11 | E12: 33 | I12: TESORERIA | J12: 1
A13: NOMINA | B13: 6 | C13: 1 | E13: 7 | I13: TI | J13: 1
A14: OPERACIONES | B14: 2 | D14: 1 | E14: 3 | I14: Total general | J14: 82
A15: TI | B15: 10 | C15: 1 | E15: 11
A16: Total general | B16: 183 | C16: 23 | D16: 32 | E16: 238
B18: =(183*100%)/238 -> 0.76890756 | C18: =(55*100%)/238 -> 0.23109244
D20: A tiempo | E20: Por fuera del tiempo
A22: Facturas entregadas 30/03/2026 | B22: 238 | D22: 183 | E22: 55
A23: Facturas de Caja Menor | B23: 40
A24: Facturas rechazadas | B24: 4
A25: Pendientes por entregar | B25: 82 | D25: 22 | E25: =B25-D25 -> 60

Sheet CONTROL GENERAL
A1: Tipo documento | B1: CUFE/CUDE | C1: Folio | D1: Prefijo | E1: Fecha Emisión | F1: Fecha Recepción | G1: MES | H1: NIT | I1: Nombre Emisor | J1: Subtotal | K1: IVA | L1: Total | M1: Responsable | N1: FECHA DE ENTREGA | O1: DÍAS DE ENTREGA A CONTABILIDAD | P1: QUIEN ENTREGA | Q1: NOMBRE A QUIEN SE DEVUELVE | R1: FECHA DEVOLUCION | S1: REINTEGRO | T1: RANGO DE ENTREGA A TESORERIA DIAS | U1: FECHA ENTREGA TESORERIA | V1: REQUIERE FIRMA DE GERENCIA | W1: FIRMADAS | X1: RANGO DÍAS DE ENTREGA
A2: Factura electrónica | B2: 0ef6b07b4cf2dd55e06ea624c82b02171fe92ef73061ac8a62c89489ed0c24e6a83be88e948a6bd96fb67ea13f0e8201 | C2: 104 | D2: JA | E2: 46023 | F2: 46023.857 | G2: =UPPER(TEXT(E2, "MMMM")) -> ENERO | H2: 15442838 | I2: GOMEZ JHON ARLEY | J2: =L2/K2 -> 6.2631579 | K2: 288496 | L2: 1806896 | M2: OPERACIONES | N2: 46027 | O2: =IFERROR(IF(-_xlfn.DAYS(E2,N2)<0,0,-_xlfn.DAYS(E2,N2)), " - ") -> 4 | P2: ANGELA FRANCO | U2: 46028 | X2: 0 a 5
A3: Factura electrónica | B3: d34baf94ce1e0e60d9018e680f6b1794d38ed6df72f72bd46baba67cf7e955d9690eda0ab6bb26fecb6bdb525e6ac2f3 | C3: 1207940 | D3: 2091 | E3: 46023 | F3: 46023.577 | G3: =UPPER(TEXT(E3, "MMMM")) -> ENERO | H3: 890903790 | I3: SEGUROS DE VIDA SURAMERICANA S.A | J3: =L3-K3 -> 1643587 | K3: 82179.35 | L3: 1725766.4 | M3: GESTION HUMANA | N3: 46037 | O3: =IFERROR(IF(-_xlfn.DAYS(E3,N3)<0,0,-_xlfn.DAYS(E3,N3)), " - ") -> 14 | P3: YENIFER PARRA | U3: 46042 | V3: NO | X3: Más de 10
A4: Factura electrónica | B4: a665605c3e744f7b8e905df90241686b912b3dbc512392e44c0d17f0ac35f1e0828e415703c87f4e4bced120e3e6c08a | C4: 34015 | D4: AEZY | E4: 46023 | F4: 46023.267 | G4: =UPPER(TEXT(E4, "MMMM")) -> ENERO | H4: 900610585 | I4: Easytaxi Colombia SAS | J4: =L4-K4 -> 1560304 | K4: 40891 | L4: 1601195 | M4: COMPRAS | N4: 46037 | O4: =IFERROR(IF(-_xlfn.DAYS(E4,N4)<0,0,-_xlfn.DAYS(E4,N4)), " - ") -> 14 | P4: YENIFER PARRA | U4: 46029 | V4: NO | X4: Más de 10
A5: Factura electrónica | B5: 2a830f0355d0bbaef7f2cbdda6631a7189a1fc3c0e3264f117de9ac19dd6d8235fbbd40c73aff9d5598bcb089cadd657 | C5: 250 | D5: FE | E5: 46023 | F5: 46023.982 | G5: =UPPER(TEXT(E5, "MMMM")) -> ENERO | H5: 901703752 | I5: ACCION LEGAL 23 S.A.S. | J5: =L5-K5 -> 14946000 | K5: 2839740 | L5: 17785740 | M5: CONTABILIDAD | N5: 46037 | O5: =IFERROR(IF(-_xlfn.DAYS(E5,N5)<0,0,-_xlfn.DAYS(E5,N5)), " - ") -> 14 | P5: ANGELA FRANCO | U5: 46028 | V5: SI | X5: Más de 10
A6: Factura electrónica | B6: 194c7373fb40685d6ed80b32a52bc4c1365388bb20d830b989d25dc1053d9cedd7495e96a95b00712bbcc90f046a3dc8 | C6: 3472 | D6: RIND | E6: 46023 | F6: 46023.156 | G6: =UPPER(TEXT(E6, "MMMM")) -> ENERO | H6: 901609691 | I6: RINDEGASTOS COLOMBIA S.A.S. | J6: =L6-K6 -> 696000 | K6: 132240 | L6: 828240 | M6: CONTABILIDAD | N6: 46037 | O6: =IFERROR(IF(-_xlfn.DAYS(E6,N6)<0,0,-_xlfn.DAYS(E6,N6)), " - ") -> 14 | P6: ANGELA FRANCO | U6: 46028 | V6: SI | X6: Más de 10
